Workbook

Sheet Semana 1
C2: Entrenador/a | D2: Tu nombre y apellido | F2: Fecha de hoy | I2: =TODAY() -> 46305 | P2: Semanas trascurridas
C3: Nombre del alumno | D3: El nombre y apellido del alumno | F3: Fecha de inicio | I3: 45901 | P3: =INT((DATEDIF($I$3,$I$2,"D")/7)) -> 57
C4: Objetivo del alumno | D4: El objetivo del alumno (pérdida de peso, aumento de la fuerza, mejora de la resistencia, etc.)
B6: DÍA 1: ESTRUCTURA | F6: Series | G6: RIR/RPE | H6: Descanso | I6: Serie 1 | K6: Serie 2 | M6: Serie 3 | O6: Serie 4 | Q6: Serie 5 | S6: Tonelaje
B7: Notas del alumno | C7: Categoría de ejercicio | D7: Ejercicios | E7: Feedback Técnico | I7: Reps | J7: Kg | K7: Reps | L7: Kg | M7: Reps | N7: Kg | O7: Reps | P7: Kg | Q7: Reps | R7: Kg
S8: =I8*J8+K8*L8+M8*N8+O8*P8+Q8*R8 -> 0
S9: =I9*J9+K9*L9+M9*N9+O9*P9+Q9*R9 -> 0
S10: =I10*J10+K10*L10+M10*N10+O10*P10+Q10*R10 -> 0
S11: =I11*J11+K11*L11+M11*N11+O11*P11+Q11*R11 -> 0
S12: =I12*J12+K12*L12+M12*N12+O12*P12+Q12*R12 -> 0
S13: =I13*J13+K13*L13+M13*N13+O13*P13+Q13*R13 -> 0
S14: =I14*J14+K14*L14+M14*N14+O14*P14+Q14*R14 -> 0
S15: =I15*J15+K15*L15+M15*N15+O15*P15+Q15*R15 -> 0
B16: Duración de la sesión | D16: DOMS | F16: GRUPO MUSCULAR | M16: PESAJE DEL DÍA | Q16: ESFUERZO GRAL.
B18: DÍA 2: ESTRUCTURA | F18: Series | G18: RIR/RPE | H18: Descanso | I18: Serie 1 | K18: Serie 2 | M18: Serie 3 | O18: Serie 4 | Q18: Serie 5 | S18: Tonelaje
B19: Notas del alumno | C19: Categoría de ejercicio | D19: Ejercicios | E19: Feedback Técnico | I19: Reps | J19: Kg | K19: Reps | L19: Kg | M19: Reps | N19: Kg | O19: Reps | P19: Kg | Q19: Reps | R19: Kg
S20: =I20*J20+K20*L20+M20*N20+O20*P20+Q20*R20 -> 0
S21: =I21*J21+K21*L21+M21*N21+O21*P21+Q21*R21 -> 0
S22: =I22*J22+K22*L22+M22*N22+O22*P22+Q22*R22 -> 0
S23: =I23*J23+K23*L23+M23*N23+O23*P23+Q23*R23 -> 0
S24: =I24*J24+K24*L24+M24*N24+O24*P24+Q24*R24 -> 0
S25: =I25*J25+K25*L25+M25*N25+O25*P25+Q25*R25 -> 0
S26: =I26*J26+K26*L26+M26*N26+O26*P26+Q26*R26 -> 0
S27: =I27*J27+K27*L27+M27*N27+O27*P27+Q27*R27 -> 0
B28: Duración de la sesión | D28: DOMS | F28: GRUPO MUSCULAR | M28: PESAJE DEL DÍA | Q28: ESFUERZO GRAL.
B30: DÍA 3: ESTRUCTURA | F30: Series | G30: RIR/RPE | H30: Descanso | I30: Serie 1 | K30: Serie 2 | M30: Serie 3 | O30: Serie 4 | Q30: Serie 5 | S30: Tonelaje
B31: Notas del alumno | C31: Categoría de ejercicio | D31: Ejercicios | E31: Feedback Técnico | I31: Reps | J31: Kg | K31: Reps | L31: Kg | M31: Reps | N31: Kg | O31: Reps | P31: Kg | Q31: Reps | R31: Kg
S32: =I32*J32+K32*L32+M32*N32+O32*P32+Q32*R32 -> 0
S33: =I33*J33+K33*L33+M33*N33+O33*P33+Q33*R33 -> 0
S34: =I34*J34+K34*L34+M34*N34+O34*P34+Q34*R34 -> 0
S35: =I35*J35+K35*L35+M35*N35+O35*P35+Q35*R35 -> 0
S36: =I36*J36+K36*L36+M36*N36+O36*P36+Q36*R36 -> 0
S37: =I37*J37+K37*L37+M37*N37+O37*P37+Q37*R37 -> 0
S38: =I38*J38+K38*L38+M38*N38+O38*P38+Q38*R38 -> 0
S39: =I39*J39+K39*L39+M39*N39+O39*P39+Q39*R39 -> 0
B40: Duración de la sesión | D40: DOMS | F40: GRUPO MUSCULAR | M40: PESAJE DEL DÍA | Q40: ESFUERZO GRAL.
B42: DÍA 4: ESTRUCTURA | F42: Series | G42: RIR/RPE | H42: Descanso | I42: Serie 1 | K42: Serie 2 | M42: Serie 3 | O42: Serie 4 | Q42: Serie 5 | S42: Tonelaje
B43: Notas del alumno | C43: Categoría de ejercicio | D43: Ejercicios | E43: Feedback Técnico | I43: Reps | J43: Kg | K43: Reps | L43: Kg | M43: Reps | N43: Kg | O43: Reps | P43: Kg | Q43: Reps | R43: Kg
S44: =I44*J44+K44*L44+M44*N44+O44*P44+Q44*R44 -> 0
S45: =I45*J45+K45*L45+M45*N45+O45*P45+Q45*R45 -> 0
...

Sheet Semana 2
C2: Entrenador/a | D2: ='Semana 1'!D2 -> Tu nombre y apellido | F2: Fecha de hoy | I2: =TODAY() -> 46305 | P2: Semanas trascurridas
C3: Nombre del alumno | D3: ='Semana 1'!D3 -> El nombre y apellido del alumno | F3: Fecha de inicio | I3: ='Semana 1'!I3 -> 45901 | P3: ='Semana 1'!P3 -> 57
B5: ='Semana 1'!B6 -> DÍA 1: ESTRUCTURA | F5: Series | G5: RIR/RPE | H5: Descanso | I5: Serie 1 | K5: Serie 2 | M5: Serie 3 | O5: Serie 4 | Q5: Serie 5 | S5: Tonelaje
B6: Notas del alumno | C6: Categoría de ejercicio | D6: Ejercicios | E6: Feedback Técnico | I6: Reps | J6: Kg | K6: Reps | L6: Kg | M6: Reps | N6: Kg | O6: Reps | P6: Kg | Q6: Reps | R6: Kg
C7: ='Semana 1'!C8 | D7: ='Semana 1'!D8 | F7: ='Semana 1'!F8 | G7: ='Semana 1'!G8 | H7: ='Semana 1'!H8 | I7: ='Semana 1'!I8 | J7: ='Semana 1'!J8 | K7: ='Semana 1'!K8 | L7: ='Semana 1'!L8 | M7: ='Semana 1'!M8 | ... R7: ='Semana 1'!R8 | S7: =I7*J7+K7*L7+M7*N7+O7*P7+Q7*R7 -> 0
C8: ='Semana 1'!C9 | D8: ='Semana 1'!D9 | F8: ='Semana 1'!F9 | G8: ='Semana 1'!G9 | H8: ='Semana 1'!H9 | I8: ='Semana 1'!I9 | J8: ='Semana 1'!J9 | K8: ='Semana 1'!K9 | L8: ='Semana 1'!L9 | M8: ='Semana 1'!M9 | ... R8: ='Semana 1'!R9 | S8: =I8*J8+K8*L8+M8*N8+O8*P8+Q8*R8 -> 0
C9: ='Semana 1'!C10 | D9: ='Semana 1'!D10 | F9: ='Semana 1'!F10 | G9: ='Semana 1'!G10 | H9: ='Semana 1'!H10 | I9: ='Semana 1'!I10 | J9: ='Semana 1'!J10 | K9: ='Semana 1'!K10 | L9: ='Semana 1'!L10 | M9: ='Semana 1'!M10 | ... R9: ='Semana 1'!R10 | S9: =I9*J9+K9*L9+M9*N9+O9*P9+Q9*R9 -> 0
C10: ='Semana 1'!C11 | D10: ='Semana 1'!D11 | F10: ='Semana 1'!F11 | G10: ='Semana 1'!G11 | H10: ='Semana 1'!H11 | I10: ='Semana 1'!I11 | J10: ='Semana 1'!J11 | K10: ='Semana 1'!K11 | L10: ='Semana 1'!L11 | M10: ='Semana 1'!M11 | ... R10: ='Semana 1'!R11 | S10: =I10*J10+K10*L10+M10*N10+O10*P10+Q10*R10 -> 0
C11: ='Semana 1'!C12 | D11: ='Semana 1'!D12 | F11: ='Semana 1'!F12 | G11: ='Semana 1'!G12 | H11: ='Semana 1'!H12 | I11: ='Semana 1'!I12 | J11: ='Semana 1'!J12 | K11: ='Semana 1'!K12 | L11: ='Semana 1'!L12 | M11: ='Semana 1'!M12 | ... R11: ='Semana 1'!R12 | S11: =I11*J11+K11*L11+M11*N11+O11*P11+Q11*R11 -> 0
C12: ='Semana 1'!C13 | D12: ='Semana 1'!D13 | F12: ='Semana 1'!F13 | G12: ='Semana 1'!G13 | H12: ='Semana 1'!H13 | I12: ='Semana 1'!I13 | J12: ='Semana 1'!J13 | K12: ='Semana 1'!K13 | L12: ='Semana 1'!L13 | M12: ='Semana 1'!M13 | ... R12: ='Semana 1'!R13 | S12: =I12*J12+K12*L12+M12*N12+O12*P12+Q12*R12 -> 0
C13: ='Semana 1'!C14 | D13: ='Semana 1'!D14 | F13: ='Semana 1'!F14 | G13: ='Semana 1'!G14 | H13: ='Semana 1'!H14 | I13: ='Semana 1'!I14 | J13: ='Semana 1'!J14 | K13: ='Semana 1'!K14 | L13: ='Semana 1'!L14 | M13: ='Semana 1'!M14 | ... R13: ='Semana 1'!R14 | S13: =I13*J13+K13*L13+M13*N13+O13*P13+Q13*R13 -> 0
C14: ='Semana 1'!C15 | D14: ='Semana 1'!D15 | F14: ='Semana 1'!F15 | G14: ='Semana 1'!G15 | H14: ='Semana 1'!H15 | I14: ='Semana 1'!I15 | J14: ='Semana 1'!J15 | K14: ='Semana 1'!K15 | L14: ='Semana 1'!L15 | M14: ='Semana 1'!M15 | ... R14: ='Semana 1'!R15 | S14: =I14*J14+K14*L14+M14*N14+O14*P14+Q14*R14 -> 0
B15: Duración de la sesión | D15: DOMS | F15: GRUPO MUSCULAR | M15: PESAJE DEL DÍA | Q15: ESFUERZO GRAL.
B17: ='Semana 1'!B18 -> DÍA 2: ESTRUCTURA | F17: Series | G17: RIR/RPE | H17: Descanso | I17: Serie 1 | K17: Serie 2 | M17: Serie 3 | O17: Serie 4 | Q17: Serie 5 | S17: Tonelaje
B18: Notas del alumno | C18: Categoría de ejercicio | D18: Ejercicios | E18: Feedback Técnico | I18: Reps | J18: Kg | K18: Reps | L18: Kg | M18: Reps | N18: Kg | O18: Reps | P18: Kg | Q18: Reps | R18: Kg
C19: ='Semana 1'!C20 | D19: ='Semana 1'!D20 | F19: ='Semana 1'!F20 | G19: ='Semana 1'!G20 | H19: ='Semana 1'!H20 | I19: ='Semana 1'!I20 | J19: ='Semana 1'!J20 | K19: ='Semana 1'!K20 | L19: ='Semana 1'!L20 | M19: ='Semana 1'!M20 | ... R19: ='Semana 1'!R20 | S19: =I19*J19+K19*L19+M19*N19+O19*P19+Q19*R19 -> 0
C20: ='Semana 1'!C21 | D20: ='Semana 1'!D21 | F20: ='Semana 1'!F21 | G20: ='Semana 1'!G21 | H20: ='Semana 1'!H21 | I20: ='Semana 1'!I21 | J20: ='Semana 1'!J21 | K20: ='Semana 1'!K21 | L20: ='Semana 1'!L21 | M20: ='Semana 1'!M21 | ... R20: ='Semana 1'!R21 | S20: =I20*J20+K20*L20+M20*N20+O20*P20+Q20*R20 -> 0
C21: ='Semana 1'!C22 | D21: ='Semana 1'!D22 | F21: ='Semana 1'!F22 | G21: ='Semana 1'!G22 | H21: ='Semana 1'!H22 | I21: ='Semana 1'!I22 | J21: ='Semana 1'!J22 | K21: ='Semana 1'!K22 | L21: ='Semana 1'!L22 | M21: ='Semana 1'!M22 | ... R21: ='Semana 1'!R22 | S21: =I21*J21+K21*L21+M21*N21+O21*P21+Q21*R21 -> 0
C22: ='Semana 1'!C23 | D22: ='Semana 1'!D23 | F22: ='Semana 1'!F23 | G22: ='Semana 1'!G23 | H22: ='Semana 1'!H23 | I22: ='Semana 1'!I23 | J22: ='Semana 1'!J23 | K22: ='Semana 1'!K23 | L22: ='Semana 1'!L23 | M22: ='Semana 1'!M23 | ... R22: ='Semana 1'!R23 | S22: =I22*J22+K22*L22+M22*N22+O22*P22+Q22*R22 -> 0
C23: ='Semana 1'!C24 | D23: ='Semana 1'!D24 | F23: ='Semana 1'!F24 | G23: ='Semana 1'!G24 | H23: ='Semana 1'!H24 | I23: ='Semana 1'!I24 | J23: ='Semana 1'!J24 | K23: ='Semana 1'!K24 | L23: ='Semana 1'!L24 | M23: ='Semana 1'!M24 | ... R23: ='Semana 1'!R24 | S23: =I23*J23+K23*L23+M23*N23+O23*P23+Q23*R23 -> 0
C24: ='Semana 1'!C25 | D24: ='Semana 1'!D25 | F24: ='Semana 1'!F25 | G24: ='Semana 1'!G25 | H24: ='Semana 1'!H25 | I24: ='Semana 1'!I25 | J24: ='Semana 1'!J25 | K24: ='Semana 1'!K25 | L24: ='Semana 1'!L25 | M24: ='Semana 1'!M25 | ... R24: ='Semana 1'!R25 | S24: =I24*J24+K24*L24+M24*N24+O24*P24+Q24*R24 -> 0
C25: ='Semana 1'!C26 | D25: ='Semana 1'!D26 | F25: ='Semana 1'!F26 | G25: ='Semana 1'!G26 | H25: ='Semana 1'!H26 | I25: ='Semana 1'!I26 | J25: ='Semana 1'!J26 | K25: ='Semana 1'!K26 | L25: ='Semana 1'!L26 | M25: ='Semana 1'!M26 | ... R25: ='Semana 1'!R26 | S25: =I25*J25+K25*L25+M25*N25+O25*P25+Q25*R25 -> 0
C26: ='Semana 1'!C27 | D26: ='Semana 1'!D27 | F26: ='Semana 1'!F27 | G26: ='Semana 1'!G27 | H26: ='Semana 1'!H27 | I26: ='Semana 1'!I27 | J26: ='Semana 1'!J27 | K26: ='Semana 1'!K27 | L26: ='Semana 1'!L27 | M26: ='Semana 1'!M27 | ... R26: ='Semana 1'!R27 | S26: =I26*J26+K26*L26+M26*N26+O26*P26+Q26*R26 -> 0
B27: Duración de la sesión | D27: DOMS | F27: GRUPO MUSCULAR | M27: PESAJE DEL DÍA | Q27: ESFUERZO GRAL.
B29: ='Semana 1'!B30 -> DÍA 3: ESTRUCTURA | F29: Series | G29: RIR/RPE | H29: Descanso | I29: Serie 1 | K29: Serie 2 | M29: Serie 3 | O29: Serie 4 | Q29: Serie 5 | S29: Tonelaje
B30: Notas del alumno | C30: Categoría de ejercicio | D30: Ejercicios | E30: Feedback Técnico | I30: Reps | J30: Kg | K30: Reps | L30: Kg | M30: Reps | N30: Kg | O30: Reps | P30: Kg | Q30: Reps | R30: Kg
C31: ='Semana 1'!C32 | D31: ='Semana 1'!D32 | F31: ='Semana 1'!F32 | G31: ='Semana 1'!G32 | H31: ='Semana 1'!H32 | I31: ='Semana 1'!I32 | J31: ='Semana 1'!J32 | K31: ='Semana 1'!K32 | L31: ='Semana 1'!L32 | M31: ='Semana 1'!M32 | ... R31: ='Semana 1'!R32 | S31: =I31*J31+K31*L31+M31*N31+O31*P31+Q31*R31 -> 0
C32: ='Semana 1'!C33 | D32: ='Semana 1'!D33 | F32: ='Semana 1'!F33 | G32: ='Semana 1'!G33 | H32: ='Semana 1'!H33 | I32: ='Semana 1'!I33 | J32: ='Semana 1'!J33 | K32: ='Semana 1'!K33 | L32: ='Semana 1'!L33 | M32: ='Semana 1'!M33 | ... R32: ='Semana 1'!R33 | S32: =I32*J32+K32*L32+M32*N32+O32*P32+Q32*R32 -> 0
C33: ='Semana 1'!C34 | D33: ='Semana 1'!D34 | F33: ='Semana 1'!F34 | G33: ='Semana 1'!G34 | H33: ='Semana 1'!H34 | I33: ='Semana 1'!I34 | J33: ='Semana 1'!J34 | K33: ='Semana 1'!K34 | L33: ='Semana 1'!L34 | M33: ='Semana 1'!M34 | ... R33: ='Semana 1'!R34 | S33: =I33*J33+K33*L33+M33*N33+O33*P33+Q33*R33 -> 0
C34: ='Semana 1'!C35 | D34: ='Semana 1'!D35 | F34: ='Semana 1'!F35 | G34: ='Semana 1'!G35 | H34: ='Semana 1'!H35 | I34: ='Semana 1'!I35 | J34: ='Semana 1'!J35 | K34: ='Semana 1'!K35 | L34: ='Semana 1'!L35 | M34: ='Semana 1'!M35 | ... R34: ='Semana 1'!R35 | S34: =I34*J34+K34*L34+M34*N34+O34*P34+Q34*R34 -> 0
C35: ='Semana 1'!C36 | D35: ='Semana 1'!D36 | F35: ='Semana 1'!F36 | G35: ='Semana 1'!G36 | H35: ='Semana 1'!H36 | I35: ='Semana 1'!I36 | J35: ='Semana 1'!J36 | K35: ='Semana 1'!K36 | L35: ='Semana 1'!L36 | M35: ='Semana 1'!M36 | ... R35: ='Semana 1'!R36 | S35: =I35*J35+K35*L35+M35*N35+O35*P35+Q35*R35 -> 0
C36: ='Semana 1'!C37 | D36: ='Semana 1'!D37 | F36: ='Semana 1'!F37 | G36: ='Semana 1'!G37 | H36: ='Semana 1'!H37 | I36: ='Semana 1'!I37 | J36: ='Semana 1'!J37 | K36: ='Semana 1'!K37 | L36: ='Semana 1'!L37 | M36: ='Semana 1'!M37 | ... R36: ='Semana 1'!R37 | S36: =I36*J36+K36*L36+M36*N36+O36*P36+Q36*R36 -> 0
C37: ='Semana 1'!C38 | D37: ='Semana 1'!D38 | F37: ='Semana 1'!F38 | G37: ='Semana 1'!G38 | H37: ='Semana 1'!H38 | I37: ='Semana 1'!I38 | J37: ='Semana 1'!J38 | K37: ='Semana 1'!K38 | L37: ='Semana 1'!L38 | M37: ='Semana 1'!M38 | ... R37: ='Semana 1'!R38 | S37: =I37*J37+K37*L37+M37*N37+O37*P37+Q37*R37 -> 0
C38: ='Semana 1'!C39 | D38: ='Semana 1'!D39 | F38: ='Semana 1'!F39 | G38: ='Semana 1'!G39 | H38: ='Semana 1'!H39 | I38: ='Semana 1'!I39 | J38: ='Semana 1'!J39 | K38: ='Semana 1'!K39 | L38: ='Semana 1'!L39 | M38: ='Semana 1'!M39 | ... R38: ='Semana 1'!R39 | S38: =I38*J38+K38*L38+M38*N38+O38*P38+Q38*R38 -> 0
B39: Duración de la sesión | D39: DOMS | F39: GRUPO MUSCULAR | M39: PESAJE DEL DÍA | Q39: ESFUERZO GRAL.
B41: ='Semana 1'!B42 -> DÍA 4: ESTRUCTURA | F41: Series | G41: RIR/RPE | H41: Descanso | I41: Serie 1 | K41: Serie 2 | M41: Serie 3 | O41: Serie 4 | Q41: Serie 5 | S41: Tonelaje
B42: Notas del alumno | C42: Categoría de ejercicio | D42: Ejercicios | E42: Feedback Técnico | I42: Reps | J42: Kg | K42: Reps | L42: Kg | M42: Reps | N42: Kg | O42: Reps | P42: Kg | Q42: Reps | R42: Kg
C43: ='Semana 1'!C44 | D43: ='Semana 1'!D44 | F43: ='Semana 1'!F44 | G43: ='Semana 1'!G44 | H43: ='Semana 1'!H44 | I43: ='Semana 1'!I44 | J43: ='Semana 1'!J44 | K43: ='Semana 1'!K44 | L43: ='Semana 1'!L44 | M43: ='Semana 1'!M44 | ... R43: ='Semana 1'!R44 | S43: =I43*J43+K43*L43+M43*N43+O43*P43+Q43*R43 -> 0
C44: ='Semana 1'!C45 | D44: ='Semana 1'!D45 | F44: ='Semana 1'!F45 | G44: ='Semana 1'!G45 | H44: ='Semana 1'!H45 | I44: ='Semana 1'!I45 | J44: ='Semana 1'!J45 | K44: ='Semana 1'!K45 | L44: ='Semana 1'!L45 | M44: ='Semana 1'!M45 | ... R44: ='Semana 1'!R45 | S44: =I44*J44+K44*L44+M44*N44+O44*P44+Q44*R44 -> 0
C45: ='Semana 1'!C46 | D45: ='Semana 1'!D46 | F45: ='Semana 1'!F46 | G45: ='Semana 1'!G46 | H45: ='Semana 1'!H46 | I45: ='Semana 1'!I46 | J45: ='Semana 1'!J46 | K45: ='Semana 1'!K46 | L45: ='Semana 1'!L46 | M45: ='Semana 1'!M46 | ... R45: ='Semana 1'!R46 | S45: =I45*J45+K45*L45+M45*N45+O45*P45+Q45*R45 -> 0
...

Sheet Semana 3
C2: Entrenador/a | D2: ='Semana 1'!D2 -> Tu nombre y apellido | F2: Fecha de hoy | I2: =TODAY() -> 46305 | P2: Semanas trascurridas
C3: Nombre del alumno | D3: ='Semana 1'!D3 -> El nombre y apellido del alumno | F3: Fecha de inicio | I3: ='Semana 1'!I3 -> 45901 | P3: ='Semana 1'!P3 -> 57
B5: ='Semana 2'!B5 -> DÍA 1: ESTRUCTURA | F5: Series | G5: RIR/RPE | H5: Descanso | I5: Serie 1 | K5: Serie 2 | M5: Serie 3 | O5: Serie 4 | Q5: Serie 5 | S5: Tonelaje
B6: Notas del alumno | C6: Categoría de ejercicio | D6: Ejercicios | E6: Feedback Técnico | I6: Reps | J6: Kg | K6: Reps | L6: Kg | M6: Reps | N6: Kg | O6: Reps | P6: Kg | Q6: Reps | R6: Kg
C7: ='Semana 2'!C7 | D7: ='Semana 2'!D7 | F7: ='Semana 2'!F7 | G7: ='Semana 2'!G7 | H7: ='Semana 2'!H7 | I7: ='Semana 2'!I7 | J7: ='Semana 2'!J7 | K7: ='Semana 2'!K7 | L7: ='Semana 2'!L7 | M7: ='Semana 2'!M7 | ... R7: ='Semana 2'!R7 | S7: =I7*J7+K7*L7+M7*N7+O7*P7+Q7*R7 -> 0
C8: ='Semana 2'!C8 | D8: ='Semana 2'!D8 | F8: ='Semana 2'!F8 | G8: ='Semana 2'!G8 | H8: ='Semana 2'!H8 | I8: ='Semana 2'!I8 | J8: ='Semana 2'!J8 | K8: ='Semana 2'!K8 | L8: ='Semana 2'!L8 | M8: ='Semana 2'!M8 | ... R8: ='Semana 2'!R8 | S8: =I8*J8+K8*L8+M8*N8+O8*P8+Q8*R8 -> 0
C9: ='Semana 2'!C9 | D9: ='Semana 2'!D9 | F9: ='Semana 2'!F9 | G9: ='Semana 2'!G9 | H9: ='Semana 2'!H9 | I9: ='Semana 2'!I9 | J9: ='Semana 2'!J9 | K9: ='Semana 2'!K9 | L9: ='Semana 2'!L9 | M9: ='Semana 2'!M9 | ... R9: ='Semana 2'!R9 | S9: =I9*J9+K9*L9+M9*N9+O9*P9+Q9*R9 -> 0
C10: ='Semana 2'!C10 | D10: ='Semana 2'!D10 | F10: ='Semana 2'!F10 | G10: ='Semana 2'!G10 | H10: ='Semana 2'!H10 | I10: ='Semana 2'!I10 | J10: ='Semana 2'!J10 | K10: ='Semana 2'!K10 | L10: ='Semana 2'!L10 | M10: ='Semana 2'!M10 | ... R10: ='Semana 2'!R10 | S10: =I10*J10+K10*L10+M10*N10+O10*P10+Q10*R10 -> 0
C11: ='Semana 2'!C11 | D11: ='Semana 2'!D11 | F11: ='Semana 2'!F11 | G11: ='Semana 2'!G11 | H11: ='Semana 2'!H11 | I11: ='Semana 2'!I11 | J11: ='Semana 2'!J11 | K11: ='Semana 2'!K11 | L11: ='Semana 2'!L11 | M11: ='Semana 2'!M11 | ... R11: ='Semana 2'!R11 | S11: =I11*J11+K11*L11+M11*N11+O11*P11+Q11*R11 -> 0
C12: ='Semana 2'!C12 | D12: ='Semana 2'!D12 | F12: ='Semana 2'!F12 | G12: ='Semana 2'!G12 | H12: ='Semana 2'!H12 | I12: ='Semana 2'!I12 | J12: ='Semana 2'!J12 | K12: ='Semana 2'!K12 | L12: ='Semana 2'!L12 | M12: ='Semana 2'!M12 | ... R12: ='Semana 2'!R12 | S12: =I12*J12+K12*L12+M12*N12+O12*P12+Q12*R12 -> 0
C13: ='Semana 2'!C13 | D13: ='Semana 2'!D13 | F13: ='Semana 2'!F13 | G13: ='Semana 2'!G13 | H13: ='Semana 2'!H13 | I13: ='Semana 2'!I13 | J13: ='Semana 2'!J13 | K13: ='Semana 2'!K13 | L13: ='Semana 2'!L13 | M13: ='Semana 2'!M13 | ... R13: ='Semana 2'!R13 | S13: =I13*J13+K13*L13+M13*N13+O13*P13+Q13*R13 -> 0
C14: ='Semana 2'!C14 | D14: ='Semana 2'!D14 | F14: ='Semana 2'!F14 | G14: ='Semana 2'!G14 | H14: ='Semana 2'!H14 | I14: ='Semana 2'!I14 | J14: ='Semana 2'!J14 | K14: ='Semana 2'!K14 | L14: ='Semana 2'!L14 | M14: ='Semana 2'!M14 | ... R14: ='Semana 2'!R14 | S14: =I14*J14+K14*L14+M14*N14+O14*P14+Q14*R14 -> 0
B15: Duración de la sesión | D15: DOMS | F15: GRUPO MUSCULAR | M15: PESAJE DEL DÍA | Q15: ESFUERZO GRAL.
B17: ='Semana 2'!B17 -> DÍA 2: ESTRUCTURA | F17: Series | G17: RIR/RPE | H17: Descanso | I17: Serie 1 | K17: Serie 2 | M17: Serie 3 | O17: Serie 4 | Q17: Serie 5 | S17: Tonelaje
B18: Notas del alumno | C18: Categoría de ejercicio | D18: Ejercicios | E18: Feedback Técnico | I18: Reps | J18: Kg | K18: Reps | L18: Kg | M18: Reps | N18: Kg | O18: Reps | P18: Kg | Q18: Reps | R18: Kg
C19: ='Semana 2'!C19 | D19: ='Semana 2'!D19 | F19: ='Semana 2'!F19 | G19: ='Semana 2'!G19 | H19: ='Semana 2'!H19 | I19: ='Semana 2'!I19 | J19: ='Semana 2'!J19 | K19: ='Semana 2'!K19 | L19: ='Semana 2'!L19 | M19: ='Semana 2'!M19 | ... R19: ='Semana 2'!R19 | S19: =I19*J19+K19*L19+M19*N19+O19*P19+Q19*R19 -> 0
C20: ='Semana 2'!C20 | D20: ='Semana 2'!D20 | F20: ='Semana 2'!F20 | G20: ='Semana 2'!G20 | H20: ='Semana 2'!H20 | I20: ='Semana 2'!I20 | J20: ='Semana 2'!J20 | K20: ='Semana 2'!K20 | L20: ='Semana 2'!L20 | M20: ='Semana 2'!M20 | ... R20: ='Semana 2'!R20 | S20: =I20*J20+K20*L20+M20*N20+O20*P20+Q20*R20 -> 0
C21: ='Semana 2'!C21 | D21: ='Semana 2'!D21 | F21: ='Semana 2'!F21 | G21: ='Semana 2'!G21 | H21: ='Semana 2'!H21 | I21: ='Semana 2'!I21 | J21: ='Semana 2'!J21 | K21: ='Semana 2'!K21 | L21: ='Semana 2'!L21 | M21: ='Semana 2'!M21 | ... R21: ='Semana 2'!R21 | S21: =I21*J21+K21*L21+M21*N21+O21*P21+Q21*R21 -> 0
C22: ='Semana 2'!C22 | D22: ='Semana 2'!D22 | F22: ='Semana 2'!F22 | G22: ='Semana 2'!G22 | H22: ='Semana 2'!H22 | I22: ='Semana 2'!I22 | J22: ='Semana 2'!J22 | K22: ='Semana 2'!K22 | L22: ='Semana 2'!L22 | M22: ='Semana 2'!M22 | ... R22: ='Semana 2'!R22 | S22: =I22*J22+K22*L22+M22*N22+O22*P22+Q22*R22 -> 0
C23: ='Semana 2'!C23 | D23: ='Semana 2'!D23 | F23: ='Semana 2'!F23 | G23: ='Semana 2'!G23 | H23: ='Semana 2'!H23 | I23: ='Semana 2'!I23 | J23: ='Semana 2'!J23 | K23: ='Semana 2'!K23 | L23: ='Semana 2'!L23 | M23: ='Semana 2'!M23 | ... R23: ='Semana 2'!R23 | S23: =I23*J23+K23*L23+M23*N23+O23*P23+Q23*R23 -> 0
C24: ='Semana 2'!C24 | D24: ='Semana 2'!D24 | F24: ='Semana 2'!F24 | G24: ='Semana 2'!G24 | H24: ='Semana 2'!H24 | I24: ='Semana 2'!I24 | J24: ='Semana 2'!J24 | K24: ='Semana 2'!K24 | L24: ='Semana 2'!L24 | M24: ='Semana 2'!M24 | ... R24: ='Semana 2'!R24 | S24: =I24*J24+K24*L24+M24*N24+O24*P24+Q24*R24 -> 0
C25: ='Semana 2'!C25 | D25: ='Semana 2'!D25 | F25: ='Semana 2'!F25 | G25: ='Semana 2'!G25 | H25: ='Semana 2'!H25 | I25: ='Semana 2'!I25 | J25: ='Semana 2'!J25 | K25: ='Semana 2'!K25 | L25: ='Semana 2'!L25 | M25: ='Semana 2'!M25 | ... R25: ='Semana 2'!R25 | S25: =I25*J25+K25*L25+M25*N25+O25*P25+Q25*R25 -> 0
C26: ='Semana 2'!C26 | D26: ='Semana 2'!D26 | F26: ='Semana 2'!F26 | G26: ='Semana 2'!G26 | H26: ='Semana 2'!H26 | I26: ='Semana 2'!I26 | J26: ='Semana 2'!J26 | K26: ='Semana 2'!K26 | L26: ='Semana 2'!L26 | M26: ='Semana 2'!M26 | ... R26: ='Semana 2'!R26 | S26: =I26*J26+K26*L26+M26*N26+O26*P26+Q26*R26 -> 0
B27: Duración de la sesión | D27: DOMS | F27: GRUPO MUSCULAR | M27: PESAJE DEL DÍA | Q27: ESFUERZO GRAL.
B29: ='Semana 2'!B29 -> DÍA 3: ESTRUCTURA | F29: Series | G29: RIR/RPE | H29: Descanso | I29: Serie 1 | K29: Serie 2 | M29: Serie 3 | O29: Serie 4 | Q29: Serie 5 | S29: Tonelaje
B30: Notas del alumno | C30: Categoría de ejercicio | D30: Ejercicios | E30: Feedback Técnico | I30: Reps | J30: Kg | K30: Reps | L30: Kg | M30: Reps | N30: Kg | O30: Reps | P30: Kg | Q30: Reps | R30: Kg
C31: ='Semana 2'!C31 | D31: ='Semana 2'!D31 | F31: ='Semana 2'!F31 | G31: ='Semana 2'!G31 | H31: ='Semana 2'!H31 | I31: ='Semana 2'!I31 | J31: ='Semana 2'!J31 | K31: ='Semana 2'!K31 | L31: ='Semana 2'!L31 | M31: ='Semana 2'!M31 | ... R31: ='Semana 2'!R31 | S31: =I31*J31+K31*L31+M31*N31+O31*P31+Q31*R31 -> 0
C32: ='Semana 2'!C32 | D32: ='Semana 2'!D32 | F32: ='Semana 2'!F32 | G32: ='Semana 2'!G32 | H32: ='Semana 2'!H32 | I32: ='Semana 2'!I32 | J32: ='Semana 2'!J32 | K32: ='Semana 2'!K32 | L32: ='Semana 2'!L32 | M32: ='Semana 2'!M32 | ... R32: ='Semana 2'!R32 | S32: =I32*J32+K32*L32+M32*N32+O32*P32+Q32*R32 -> 0
C33: ='Semana 2'!C33 | D33: ='Semana 2'!D33 | F33: ='Semana 2'!F33 | G33: ='Semana 2'!G33 | H33: ='Semana 2'!H33 | I33: ='Semana 2'!I33 | J33: ='Semana 2'!J33 | K33: ='Semana 2'!K33 | L33: ='Semana 2'!L33 | M33: ='Semana 2'!M33 | ... R33: ='Semana 2'!R33 | S33: =I33*J33+K33*L33+M33*N33+O33*P33+Q33*R33 -> 0
C34: ='Semana 2'!C34 | D34: ='Semana 2'!D34 | F34: ='Semana 2'!F34 | G34: ='Semana 2'!G34 | H34: ='Semana 2'!H34 | I34: ='Semana 2'!I34 | J34: ='Semana 2'!J34 | K34: ='Semana 2'!K34 | L34: ='Semana 2'!L34 | M34: ='Semana 2'!M34 | ... R34: ='Semana 2'!R34 | S34: =I34*J34+K34*L34+M34*N34+O34*P34+Q34*R34 -> 0
C35: ='Semana 2'!C35 | D35: ='Semana 2'!D35 | F35: ='Semana 2'!F35 | G35: ='Semana 2'!G35 | H35: ='Semana 2'!H35 | I35: ='Semana 2'!I35 | J35: ='Semana 2'!J35 | K35: ='Semana 2'!K35 | L35: ='Semana 2'!L35 | M35: ='Semana 2'!M35 | ... R35: ='Semana 2'!R35 | S35: =I35*J35+K35*L35+M35*N35+O35*P35+Q35*R35 -> 0
C36: ='Semana 2'!C36 | D36: ='Semana 2'!D36 | F36: ='Semana 2'!F36 | G36: ='Semana 2'!G36 | H36: ='Semana 2'!H36 | I36: ='Semana 2'!I36 | J36: ='Semana 2'!J36 | K36: ='Semana 2'!K36 | L36: ='Semana 2'!L36 | M36: ='Semana 2'!M36 | ... R36: ='Semana 2'!R36 | S36: =I36*J36+K36*L36+M36*N36+O36*P36+Q36*R36 -> 0
C37: ='Semana 2'!C37 | D37: ='Semana 2'!D37 | F37: ='Semana 2'!F37 | G37: ='Semana 2'!G37 | H37: ='Semana 2'!H37 | I37: ='Semana 2'!I37 | J37: ='Semana 2'!J37 | K37: ='Semana 2'!K37 | L37: ='Semana 2'!L37 | M37: ='Semana 2'!M37 | ... R37: ='Semana 2'!R37 | S37: =I37*J37+K37*L37+M37*N37+O37*P37+Q37*R37 -> 0
C38: ='Semana 2'!C38 | D38: ='Semana 2'!D38 | F38: ='Semana 2'!F38 | G38: ='Semana 2'!G38 | H38: ='Semana 2'!H38 | I38: ='Semana 2'!I38 | J38: ='Semana 2'!J38 | K38: ='Semana 2'!K38 | L38: ='Semana 2'!L38 | M38: ='Semana 2'!M38 | ... R38: ='Semana 2'!R38 | S38: =I38*J38+K38*L38+M38*N38+O38*P38+Q38*R38 -> 0
B39: Duración de la sesión | D39: DOMS | F39: GRUPO MUSCULAR | M39: PESAJE DEL DÍA | Q39: ESFUERZO GRAL.
B41: ='Semana 2'!B41 -> DÍA 4: ESTRUCTURA | F41: Series | G41: RIR/RPE | H41: Descanso | I41: Serie 1 | K41: Serie 2 | M41: Serie 3 | O41: Serie 4 | Q41: Serie 5 | S41: Tonelaje
B42: Notas del alumno | C42: Categoría de ejercicio | D42: Ejercicios | E42: Feedback Técnico | I42: Reps | J42: Kg | K42: Reps | L42: Kg | M42: Reps | N42: Kg | O42: Reps | P42: Kg | Q42: Reps | R42: Kg
C43: ='Semana 2'!C43 | D43: ='Semana 2'!D43 | F43: ='Semana 2'!F43 | G43: ='Semana 2'!G43 | H43: ='Semana 2'!H43 | I43: ='Semana 2'!I43 | J43: ='Semana 2'!J43 | K43: ='Semana 2'!K43 | L43: ='Semana 2'!L43 | M43: ='Semana 2'!M43 | ... R43: ='Semana 2'!R43 | S43: =I43*J43+K43*L43+M43*N43+O43*P43+Q43*R43 -> 0
C44: ='Semana 2'!C44 | D44: ='Semana 2'!D44 | F44: ='Semana 2'!F44 | G44: ='Semana 2'!G44 | H44: ='Semana 2'!H44 | I44: ='Semana 2'!I44 | J44: ='Semana 2'!J44 | K44: ='Semana 2'!K44 | L44: ='Semana 2'!L44 | M44: ='Semana 2'!M44 | ... R44: ='Semana 2'!R44 | S44: =I44*J44+K44*L44+M44*N44+O44*P44+Q44*R44 -> 0
C45: ='Semana 2'!C45 | D45: ='Semana 2'!D45 | F45: ='Semana 2'!F45 | G45: ='Semana 2'!G45 | H45: ='Semana 2'!H45 | I45: ='Semana 2'!I45 | J45: ='Semana 2'!J45 | K45: ='Semana 2'!K45 | L45: ='Semana 2'!L45 | M45: ='Semana 2'!M45 | ... R45: ='Semana 2'!R45 | S45: =I45*J45+K45*L45+M45*N45+O45*P45+Q45*R45 -> 0
...

Sheet Semana 4
C2: Entrenador/a | D2: ='Semana 1'!D2 -> Tu nombre y apellido | F2: Fecha de hoy | I2: =TODAY() -> 46305 | P2: Semanas trascurridas
C3: Nombre del alumno | D3: ='Semana 1'!D3 -> El nombre y apellido del alumno | F3: Fecha de inicio | I3: ='Semana 1'!I3 -> 45901 | P3: ='Semana 1'!P3 -> 57
B5: ='Semana 3'!B5 -> DÍA 1: ESTRUCTURA | F5: Series | G5: RIR/RPE | H5: Descanso | I5: Serie 1 | K5: Serie 2 | M5: Serie 3 | O5: Serie 4 | Q5: Serie 5 | S5: Tonelaje
B6: Notas del alumno | C6: Categoría de ejercicio | D6: Ejercicios | E6: Feedback Técnico | I6: Reps | J6: Kg | K6: Reps | L6: Kg | M6: Reps | N6: Kg | O6: Reps | P6: Kg | Q6: Reps | R6: Kg
C7: ='Semana 3'!C7 | D7: ='Semana 3'!D7 | F7: ='Semana 3'!F7 | G7: ='Semana 3'!G7 | H7: ='Semana 3'!H7 | I7: ='Semana 3'!I7 | J7: ='Semana 3'!J7 | K7: ='Semana 3'!K7 | L7: ='Semana 3'!L7 | M7: ='Semana 3'!M7 | ... R7: ='Semana 3'!R7 | S7: =I7*J7+K7*L7+M7*N7+O7*P7+Q7*R7 -> 0
C8: ='Semana 3'!C8 | D8: ='Semana 3'!D8 | F8: ='Semana 3'!F8 | G8: ='Semana 3'!G8 | H8: ='Semana 3'!H8 | I8: ='Semana 3'!I8 | J8: ='Semana 3'!J8 | K8: ='Semana 3'!K8 | L8: ='Semana 3'!L8 | M8: ='Semana 3'!M8 | ... R8: ='Semana 3'!R8 | S8: =I8*J8+K8*L8+M8*N8+O8*P8+Q8*R8 -> 0
C9: ='Semana 3'!C9 | D9: ='Semana 3'!D9 | F9: ='Semana 3'!F9 | G9: ='Semana 3'!G9 | H9: ='Semana 3'!H9 | I9: ='Semana 3'!I9 | J9: ='Semana 3'!J9 | K9: ='Semana 3'!K9 | L9: ='Semana 3'!L9 | M9: ='Semana 3'!M9 | ... R9: ='Semana 3'!R9 | S9: =I9*J9+K9*L9+M9*N9+O9*P9+Q9*R9 -> 0
C10: ='Semana 3'!C10 | D10: ='Semana 3'!D10 | F10: ='Semana 3'!F10 | G10: ='Semana 3'!G10 | H10: ='Semana 3'!H10 | I10: ='Semana 3'!I10 | J10: ='Semana 3'!J10 | K10: ='Semana 3'!K10 | L10: ='Semana 3'!L10 | M10: ='Semana 3'!M10 | ... R10: ='Semana 3'!R10 | S10: =I10*J10+K10*L10+M10*N10+O10*P10+Q10*R10 -> 0
C11: ='Semana 3'!C11 | D11: ='Semana 3'!D11 | F11: ='Semana 3'!F11 | G11: ='Semana 3'!G11 | H11: ='Semana 3'!H11 | I11: ='Semana 3'!I11 | J11: ='Semana 3'!J11 | K11: ='Semana 3'!K11 | L11: ='Semana 3'!L11 | M11: ='Semana 3'!M11 | ... R11: ='Semana 3'!R11 | S11: =I11*J11+K11*L11+M11*N11+O11*P11+Q11*R11 -> 0
C12: ='Semana 3'!C12 | D12: ='Semana 3'!D12 | F12: ='Semana 3'!F12 | G12: ='Semana 3'!G12 | H12: ='Semana 3'!H12 | I12: ='Semana 3'!I12 | J12: ='Semana 3'!J12 | K12: ='Semana 3'!K12 | L12: ='Semana 3'!L12 | M12: ='Semana 3'!M12 | ... R12: ='Semana 3'!R12 | S12: =I12*J12+K12*L12+M12*N12+O12*P12+Q12*R12 -> 0
C13: ='Semana 3'!C13 | D13: ='Semana 3'!D13 | F13: ='Semana 3'!F13 | G13: ='Semana 3'!G13 | H13: ='Semana 3'!H13 | I13: ='Semana 3'!I13 | J13: ='Semana 3'!J13 | K13: ='Semana 3'!K13 | L13: ='Semana 3'!L13 | M13: ='Semana 3'!M13 | ... R13: ='Semana 3'!R13 | S13: =I13*J13+K13*L13+M13*N13+O13*P13+Q13*R13 -> 0
C14: ='Semana 3'!C14 | D14: ='Semana 3'!D14 | F14: ='Semana 3'!F14 | G14: ='Semana 3'!G14 | H14: ='Semana 3'!H14 | I14: ='Semana 3'!I14 | J14: ='Semana 3'!J14 | K14: ='Semana 3'!K14 | L14: ='Semana 3'!L14 | M14: ='Semana 3'!M14 | ... R14: ='Semana 3'!R14 | S14: =I14*J14+K14*L14+M14*N14+O14*P14+Q14*R14 -> 0
B15: Duración de la sesión | D15: DOMS | F15: GRUPO MUSCULAR | M15: PESAJE DEL DÍA | Q15: ESFUERZO GRAL.
B17: ='Semana 3'!B17 -> DÍA 2: ESTRUCTURA | F17: Series | G17: RIR/RPE | H17: Descanso | I17: Serie 1 | K17: Serie 2 | M17: Serie 3 | O17: Serie 4 | Q17: Serie 5 | S17: Tonelaje
B18: Notas del alumno | C18: Categoría de ejercicio | D18: Ejercicios | E18: Feedback Técnico | I18: Reps | J18: Kg | K18: Reps | L18: Kg | M18: Reps | N18: Kg | O18: Reps | P18: Kg | Q18: Reps | R18: Kg
C19: ='Semana 3'!C19 | D19: ='Semana 3'!D19 | F19: ='Semana 3'!F19 | G19: ='Semana 3'!G19 | H19: ='Semana 3'!H19 | I19: ='Semana 3'!I19 | J19: ='Semana 3'!J19 | K19: ='Semana 3'!K19 | L19: ='Semana 3'!L19 | M19: ='Semana 3'!M19 | ... R19: ='Semana 3'!R19 | S19: =I19*J19+K19*L19+M19*N19+O19*P19+Q19*R19 -> 0
C20: ='Semana 3'!C20 | D20: ='Semana 3'!D20 | F20: ='Semana 3'!F20 | G20: ='Semana 3'!G20 | H20: ='Semana 3'!H20 | I20: ='Semana 3'!I20 | J20: ='Semana 3'!J20 | K20: ='Semana 3'!K20 | L20: ='Semana 3'!L20 | M20: ='Semana 3'!M20 | ... R20: ='Semana 3'!R20 | S20: =I20*J20+K20*L20+M20*N20+O20*P20+Q20*R20 -> 0
C21: ='Semana 3'!C21 | D21: ='Semana 3'!D21 | F21: ='Semana 3'!F21 | G21: ='Semana 3'!G21 | H21: ='Semana 3'!H21 | I21: ='Semana 3'!I21 | J21: ='Semana 3'!J21 | K21: ='Semana 3'!K21 | L21: ='Semana 3'!L21 | M21: ='Semana 3'!M21 | ... R21: ='Semana 3'!R21 | S21: =I21*J21+K21*L21+M21*N21+O21*P21+Q21*R21 -> 0
C22: ='Semana 3'!C22 | D22: ='Semana 3'!D22 | F22: ='Semana 3'!F22 | G22: ='Semana 3'!G22 | H22: ='Semana 3'!H22 | I22: ='Semana 3'!I22 | J22: ='Semana 3'!J22 | K22: ='Semana 3'!K22 | L22: ='Semana 3'!L22 | M22: ='Semana 3'!M22 | ... R22: ='Semana 3'!R22 | S22: =I22*J22+K22*L22+M22*N22+O22*P22+Q22*R22 -> 0
C23: ='Semana 3'!C23 | D23: ='Semana 3'!D23 | F23: ='Semana 3'!F23 | G23: ='Semana 3'!G23 | H23: ='Semana 3'!H23 | I23: ='Semana 3'!I23 | J23: ='Semana 3'!J23 | K23: ='Semana 3'!K23 | L23: ='Semana 3'!L23 | M23: ='Semana 3'!M23 | ... R23: ='Semana 3'!R23 | S23: =I23*J23+K23*L23+M23*N23+O23*P23+Q23*R23 -> 0
C24: ='Semana 3'!C24 | D24: ='Semana 3'!D24 | F24: ='Semana 3'!F24 | G24: ='Semana 3'!G24 | H24: ='Semana 3'!H24 | I24: ='Semana 3'!I24 | J24: ='Semana 3'!J24 | K24: ='Semana 3'!K24 | L24: ='Semana 3'!L24 | M24: ='Semana 3'!M24 | ... R24: ='Semana 3'!R24 | S24: =I24*J24+K24*L24+M24*N24+O24*P24+Q24*R24 -> 0
C25: ='Semana 3'!C25 | D25: ='Semana 3'!D25 | F25: ='Semana 3'!F25 | G25: ='Semana 3'!G25 | H25: ='Semana 3'!H25 | I25: ='Semana 3'!I25 | J25: ='Semana 3'!J25 | K25: ='Semana 3'!K25 | L25: ='Semana 3'!L25 | M25: ='Semana 3'!M25 | ... R25: ='Semana 3'!R25 | S25: =I25*J25+K25*L25+M25*N25+O25*P25+Q25*R25 -> 0
C26: ='Semana 3'!C26 | D26: ='Semana 3'!D26 | F26: ='Semana 3'!F26 | G26: ='Semana 3'!G26 | H26: ='Semana 3'!H26 | I26: ='Semana 3'!I26 | J26: ='Semana 3'!J26 | K26: ='Semana 3'!K26 | L26: ='Semana 3'!L26 | M26: ='Semana 3'!M26 | ... R26: ='Semana 3'!R26 | S26: =I26*J26+K26*L26+M26*N26+O26*P26+Q26*R26 -> 0
B27: Duración de la sesión | D27: DOMS | F27: GRUPO MUSCULAR | M27: PESAJE DEL DÍA | Q27: ESFUERZO GRAL.
B29: ='Semana 3'!B29 -> DÍA 3: ESTRUCTURA | F29: Series | G29: RIR/RPE | H29: Descanso | I29: Serie 1 | K29: Serie 2 | M29: Serie 3 | O29: Serie 4 | Q29: Serie 5 | S29: Tonelaje
B30: Notas del alumno | C30: Categoría de ejercicio | D30: Ejercicios | E30: Feedback Técnico | I30: Reps | J30: Kg | K30: Reps | L30: Kg | M30: Reps | N30: Kg | O30: Reps | P30: Kg | Q30: Reps | R30: Kg
C31: ='Semana 3'!C31 | D31: ='Semana 3'!D31 | F31: ='Semana 3'!F31 | G31: ='Semana 3'!G31 | H31: ='Semana 3'!H31 | I31: ='Semana 3'!I31 | J31: ='Semana 3'!J31 | K31: ='Semana 3'!K31 | L31: ='Semana 3'!L31 | M31: ='Semana 3'!M31 | ... R31: ='Semana 3'!R31 | S31: =I31*J31+K31*L31+M31*N31+O31*P31+Q31*R31 -> 0
C32: ='Semana 3'!C32 | D32: ='Semana 3'!D32 | F32: ='Semana 3'!F32 | G32: ='Semana 3'!G32 | H32: ='Semana 3'!H32 | I32: ='Semana 3'!I32 | J32: ='Semana 3'!J32 | K32: ='Semana 3'!K32 | L32: ='Semana 3'!L32 | M32: ='Semana 3'!M32 | ... R32: ='Semana 3'!R32 | S32: =I32*J32+K32*L32+M32*N32+O32*P32+Q32*R32 -> 0
C33: ='Semana 3'!C33 | D33: ='Semana 3'!D33 | F33: ='Semana 3'!F33 | G33: ='Semana 3'!G33 | H33: ='Semana 3'!H33 | I33: ='Semana 3'!I33 | J33: ='Semana 3'!J33 | K33: ='Semana 3'!K33 | L33: ='Semana 3'!L33 | M33: ='Semana 3'!M33 | ... R33: ='Semana 3'!R33 | S33: =I33*J33+K33*L33+M33*N33+O33*P33+Q33*R33 -> 0
C34: ='Semana 3'!C34 | D34: ='Semana 3'!D34 | F34: ='Semana 3'!F34 | G34: ='Semana 3'!G34 | H34: ='Semana 3'!H34 | I34: ='Semana 3'!I34 | J34: ='Semana 3'!J34 | K34: ='Semana 3'!K34 | L34: ='Semana 3'!L34 | M34: ='Semana 3'!M34 | ... R34: ='Semana 3'!R34 | S34: =I34*J34+K34*L34+M34*N34+O34*P34+Q34*R34 -> 0
C35: ='Semana 3'!C35 | D35: ='Semana 3'!D35 | F35: ='Semana 3'!F35 | G35: ='Semana 3'!G35 | H35: ='Semana 3'!H35 | I35: ='Semana 3'!I35 | J35: ='Semana 3'!J35 | K35: ='Semana 3'!K35 | L35: ='Semana 3'!L35 | M35: ='Semana 3'!M35 | ... R35: ='Semana 3'!R35 | S35: =I35*J35+K35*L35+M35*N35+O35*P35+Q35*R35 -> 0
C36: ='Semana 3'!C36 | D36: ='Semana 3'!D36 | F36: ='Semana 3'!F36 | G36: ='Semana 3'!G36 | H36: ='Semana 3'!H36 | I36: ='Semana 3'!I36 | J36: ='Semana 3'!J36 | K36: ='Semana 3'!K36 | L36: ='Semana 3'!L36 | M36: ='Semana 3'!M36 | ... R36: ='Semana 3'!R36 | S36: =I36*J36+K36*L36+M36*N36+O36*P36+Q36*R36 -> 0
C37: ='Semana 3'!C37 | D37: ='Semana 3'!D37 | F37: ='Semana 3'!F37 | G37: ='Semana 3'!G37 | H37: ='Semana 3'!H37 | I37: ='Semana 3'!I37 | J37: ='Semana 3'!J37 | K37: ='Semana 3'!K37 | L37: ='Semana 3'!L37 | M37: ='Semana 3'!M37 | ... R37: ='Semana 3'!R37 | S37: =I37*J37+K37*L37+M37*N37+O37*P37+Q37*R37 -> 0
C38: ='Semana 3'!C38 | D38: ='Semana 3'!D38 | F38: ='Semana 3'!F38 | G38: ='Semana 3'!G38 | H38: ='Semana 3'!H38 | I38: ='Semana 3'!I38 | J38: ='Semana 3'!J38 | K38: ='Semana 3'!K38 | L38: ='Semana 3'!L38 | M38: ='Semana 3'!M38 | ... R38: ='Semana 3'!R38 | S38: =I38*J38+K38*L38+M38*N38+O38*P38+Q38*R38 -> 0
B39: Duración de la sesión | D39: DOMS | F39: GRUPO MUSCULAR | M39: PESAJE DEL DÍA | Q39: ESFUERZO GRAL.
B41: ='Semana 3'!B41 -> DÍA 4: ESTRUCTURA | F41: Series | G41: RIR/RPE | H41: Descanso | I41: Serie 1 | K41: Serie 2 | M41: Serie 3 | O41: Serie 4 | Q41: Serie 5 | S41: Tonelaje
B42: Notas del alumno | C42: Categoría de ejercicio | D42: Ejercicios | E42: Feedback Técnico | I42: Reps | J42: Kg | K42: Reps | L42: Kg | M42: Reps | N42: Kg | O42: Reps | P42: Kg | Q42: Reps | R42: Kg
C43: ='Semana 3'!C43 | D43: ='Semana 3'!D43 | F43: ='Semana 3'!F43 | G43: ='Semana 3'!G43 | H43: ='Semana 3'!H43 | I43: ='Semana 3'!I43 | J43: ='Semana 3'!J43 | K43: ='Semana 3'!K43 | L43: ='Semana 3'!L43 | M43: ='Semana 3'!M43 | ... R43: ='Semana 3'!R43 | S43: =I43*J43+K43*L43+M43*N43+O43*P43+Q43*R43 -> 0
C44: ='Semana 3'!C44 | D44: ='Semana 3'!D44 | F44: ='Semana 3'!F44 | G44: ='Semana 3'!G44 | H44: ='Semana 3'!H44 | I44: ='Semana 3'!I44 | J44: ='Semana 3'!J44 | K44: ='Semana 3'!K44 | L44: ='Semana 3'!L44 | M44: ='Semana 3'!M44 | ... R44: ='Semana 3'!R44 | S44: =I44*J44+K44*L44+M44*N44+O44*P44+Q44*R44 -> 0
C45: ='Semana 3'!C45 | D45: ='Semana 3'!D45 | F45: ='Semana 3'!F45 | G45: ='Semana 3'!G45 | H45: ='Semana 3'!H45 | I45: ='Semana 3'!I45 | J45: ='Semana 3'!J45 | K45: ='Semana 3'!K45 | L45: ='Semana 3'!L45 | M45: ='Semana 3'!M45 | ... R45: ='Semana 3'!R45 | S45: =I45*J45+K45*L45+M45*N45+O45*P45+Q45*R45 -> 0
...

Sheet Semana 5
C2: Entrenador/a | D2: ='Semana 1'!D2 -> Tu nombre y apellido | F2: Fecha de hoy | I2: =TODAY() -> 46305 | P2: Semanas trascurridas
C3: Nombre del alumno | D3: ='Semana 1'!D3 -> El nombre y apellido del alumno | F3: Fecha de inicio | I3: ='Semana 1'!I3 -> 45901 | P3: ='Semana 1'!P3 -> 57
B5: ='Semana 4'!B5 -> DÍA 1: ESTRUCTURA | F5: Series | G5: RIR/RPE | H5: Descanso | I5: Serie 1 | K5: Serie 2 | M5: Serie 3 | O5: Serie 4 | Q5: Serie 5 | S5: Tonelaje
B6: Notas del alumno | C6: Categoría de ejercicio | D6: Ejercicios | E6: Feedback Técnico | I6: Reps | J6: Kg | K6: Reps | L6: Kg | M6: Reps | N6: Kg | O6: Reps | P6: Kg | Q6: Reps | R6: Kg
C7: ='Semana 4'!C7 | D7: ='Semana 4'!D7 | F7: ='Semana 4'!F7 | G7: ='Semana 4'!G7 | H7: ='Semana 4'!H7 | I7: ='Semana 4'!I7 | J7: ='Semana 4'!J7 | K7: ='Semana 4'!K7 | L7: ='Semana 4'!L7 | M7: ='Semana 4'!M7 | ... R7: ='Semana 4'!R7 | S7: =I7*J7+K7*L7+M7*N7+O7*P7+Q7*R7 -> 0
C8: ='Semana 4'!C8 | D8: ='Semana 4'!D8 | F8: ='Semana 4'!F8 | G8: ='Semana 4'!G8 | H8: ='Semana 4'!H8 | I8: ='Semana 4'!I8 | J8: ='Semana 4'!J8 | K8: ='Semana 4'!K8 | L8: ='Semana 4'!L8 | M8: ='Semana 4'!M8 | ... R8: ='Semana 4'!R8 | S8: =I8*J8+K8*L8+M8*N8+O8*P8+Q8*R8 -> 0
C9: ='Semana 4'!C9 | D9: ='Semana 4'!D9 | F9: ='Semana 4'!F9 | G9: ='Semana 4'!G9 | H9: ='Semana 4'!H9 | I9: ='Semana 4'!I9 | J9: ='Semana 4'!J9 | K9: ='Semana 4'!K9 | L9: ='Semana 4'!L9 | M9: ='Semana 4'!M9 | ... R9: ='Semana 4'!R9 | S9: =I9*J9+K9*L9+M9*N9+O9*P9+Q9*R9 -> 0
C10: ='Semana 4'!C10 | D10: ='Semana 4'!D10 | F10: ='Semana 4'!F10 | G10: ='Semana 4'!G10 | H10: ='Semana 4'!H10 | I10: ='Semana 4'!I10 | J10: ='Semana 4'!J10 | K10: ='Semana 4'!K10 | L10: ='Semana 4'!L10 | M10: ='Semana 4'!M10 | ... R10: ='Semana 4'!R10 | S10: =I10*J10+K10*L10+M10*N10+O10*P10+Q10*R10 -> 0
C11: ='Semana 4'!C11 | D11: ='Semana 4'!D11 | F11: ='Semana 4'!F11 | G11: ='Semana 4'!G11 | H11: ='Semana 4'!H11 | I11: ='Semana 4'!I11 | J11: ='Semana 4'!J11 | K11: ='Semana 4'!K11 | L11: ='Semana 4'!L11 | M11: ='Semana 4'!M11 | ... R11: ='Semana 4'!R11 | S11: =I11*J11+K11*L11+M11*N11+O11*P11+Q11*R11 -> 0
C12: ='Semana 4'!C12 | D12: ='Semana 4'!D12 | F12: ='Semana 4'!F12 | G12: ='Semana 4'!G12 | H12: ='Semana 4'!H12 | I12: ='Semana 4'!I12 | J12: ='Semana 4'!J12 | K12: ='Semana 4'!K12 | L12: ='Semana 4'!L12 | M12: ='Semana 4'!M12 | ... R12: ='Semana 4'!R12 | S12: =I12*J12+K12*L12+M12*N12+O12*P12+Q12*R12 -> 0
C13: ='Semana 4'!C13 | D13: ='Semana 4'!D13 | F13: ='Semana 4'!F13 | G13: ='Semana 4'!G13 | H13: ='Semana 4'!H13 | I13: ='Semana 4'!I13 | J13: ='Semana 4'!J13 | K13: ='Semana 4'!K13 | L13: ='Semana 4'!L13 | M13: ='Semana 4'!M13 | ... R13: ='Semana 4'!R13 | S13: =I13*J13+K13*L13+M13*N13+O13*P13+Q13*R13 -> 0
C14: ='Semana 4'!C14 | D14: ='Semana 4'!D14 | F14: ='Semana 4'!F14 | G14: ='Semana 4'!G14 | H14: ='Semana 4'!H14 | I14: ='Semana 4'!I14 | J14: ='Semana 4'!J14 | K14: ='Semana 4'!K14 | L14: ='Semana 4'!L14 | M14: ='Semana 4'!M14 | ... R14: ='Semana 4'!R14 | S14: =I14*J14+K14*L14+M14*N14+O14*P14+Q14*R14 -> 0
B15: Duración de la sesión | D15: DOMS | F15: GRUPO MUSCULAR | M15: PESAJE DEL DÍA | Q15: ESFUERZO GRAL.
B17: ='Semana 4'!B17 -> DÍA 2: ESTRUCTURA | F17: Series | G17: RIR/RPE | H17: Descanso | I17: Serie 1 | K17: Serie 2 | M17: Serie 3 | O17: Serie 4 | Q17: Serie 5 | S17: Tonelaje
B18: Notas del alumno | C18: Categoría de ejercicio | D18: Ejercicios | E18: Feedback Técnico | I18: Reps | J18: Kg | K18: Reps | L18: Kg | M18: Reps | N18: Kg | O18: Reps | P18: Kg | Q18: Reps | R18: Kg
C19: ='Semana 4'!C19 | D19: ='Semana 4'!D19 | F19: ='Semana 4'!F19 | G19: ='Semana 4'!G19 | H19: ='Semana 4'!H19 | I19: ='Semana 4'!I19 | J19: ='Semana 4'!J19 | K19: ='Semana 4'!K19 | L19: ='Semana 4'!L19 | M19: ='Semana 4'!M19 | ... R19: ='Semana 4'!R19 | S19: =I19*J19+K19*L19+M19*N19+O19*P19+Q19*R19 -> 0
C20: ='Semana 4'!C20 | D20: ='Semana 4'!D20 | F20: ='Semana 4'!F20 | G20: ='Semana 4'!G20 | H20: ='Semana 4'!H20 | I20: ='Semana 4'!I20 | J20: ='Semana 4'!J20 | K20: ='Semana 4'!K20 | L20: ='Semana 4'!L20 | M20: ='Semana 4'!M20 | ... R20: ='Semana 4'!R20 | S20: =I20*J20+K20*L20+M20*N20+O20*P20+Q20*R20 -> 0
C21: ='Semana 4'!C21 | D21: ='Semana 4'!D21 | F21: ='Semana 4'!F21 | G21: ='Semana 4'!G21 | H21: ='Semana 4'!H21 | I21: ='Semana 4'!I21 | J21: ='Semana 4'!J21 | K21: ='Semana 4'!K21 | L21: ='Semana 4'!L21 | M21: ='Semana 4'!M21 | ... R21: ='Semana 4'!R21 | S21: =I21*J21+K21*L21+M21*N21+O21*P21+Q21*R21 -> 0
C22: ='Semana 4'!C22 | D22: ='Semana 4'!D22 | F22: ='Semana 4'!F22 | G22: ='Semana 4'!G22 | H22: ='Semana 4'!H22 | I22: ='Semana 4'!I22 | J22: ='Semana 4'!J22 | K22: ='Semana 4'!K22 | L22: ='Semana 4'!L22 | M22: ='Semana 4'!M22 | ... R22: ='Semana 4'!R22 | S22: =I22*J22+K22*L22+M22*N22+O22*P22+Q22*R22 -> 0
C23: ='Semana 4'!C23 | D23: ='Semana 4'!D23 | F23: ='Semana 4'!F23 | G23: ='Semana 4'!G23 | H23: ='Semana 4'!H23 | I23: ='Semana 4'!I23 | J23: ='Semana 4'!J23 | K23: ='Semana 4'!K23 | L23: ='Semana 4'!L23 | M23: ='Semana 4'!M23 | ... R23: ='Semana 4'!R23 | S23: =I23*J23+K23*L23+M23*N23+O23*P23+Q23*R23 -> 0
C24: ='Semana 4'!C24 | D24: ='Semana 4'!D24 | F24: ='Semana 4'!F24 | G24: ='Semana 4'!G24 | H24: ='Semana 4'!H24 | I24: ='Semana 4'!I24 | J24: ='Semana 4'!J24 | K24: ='Semana 4'!K24 | L24: ='Semana 4'!L24 | M24: ='Semana 4'!M24 | ... R24: ='Semana 4'!R24 | S24: =I24*J24+K24*L24+M24*N24+O24*P24+Q24*R24 -> 0
C25: ='Semana 4'!C25 | D25: ='Semana 4'!D25 | F25: ='Semana 4'!F25 | G25: ='Semana 4'!G25 | H25: ='Semana 4'!H25 | I25: ='Semana 4'!I25 | J25: ='Semana 4'!J25 | K25: ='Semana 4'!K25 | L25: ='Semana 4'!L25 | M25: ='Semana 4'!M25 | ... R25: ='Semana 4'!R25 | S25: =I25*J25+K25*L25+M25*N25+O25*P25+Q25*R25 -> 0
C26: ='Semana 4'!C26 | D26: ='Semana 4'!D26 | F26: ='Semana 4'!F26 | G26: ='Semana 4'!G26 | H26: ='Semana 4'!H26 | I26: ='Semana 4'!I26 | J26: ='Semana 4'!J26 | K26: ='Semana 4'!K26 | L26: ='Semana 4'!L26 | M26: ='Semana 4'!M26 | ... R26: ='Semana 4'!R26 | S26: =I26*J26+K26*L26+M26*N26+O26*P26+Q26*R26 -> 0
B27: Duración de la sesión | D27: DOMS | F27: GRUPO MUSCULAR | M27: PESAJE DEL DÍA | Q27: ESFUERZO GRAL.
B29: ='Semana 4'!B29 -> DÍA 3: ESTRUCTURA | F29: Series | G29: RIR/RPE | H29: Descanso | I29: Serie 1 | K29: Serie 2 | M29: Serie 3 | O29: Serie 4 | Q29: Serie 5 | S29: Tonelaje
B30: Notas del alumno | C30: Categoría de ejercicio | D30: Ejercicios | E30: Feedback Técnico | I30: Reps | J30: Kg | K30: Reps | L30: Kg | M30: Reps | N30: Kg | O30: Reps | P30: Kg | Q30: Reps | R30: Kg
C31: ='Semana 4'!C31 | D31: ='Semana 4'!D31 | F31: ='Semana 4'!F31 | G31: ='Semana 4'!G31 | H31: ='Semana 4'!H31 | I31: ='Semana 4'!I31 | J31: ='Semana 4'!J31 | K31: ='Semana 4'!K31 | L31: ='Semana 4'!L31 | M31: ='Semana 4'!M31 | ... R31: ='Semana 4'!R31 | S31: =I31*J31+K31*L31+M31*N31+O31*P31+Q31*R31 -> 0
C32: ='Semana 4'!C32 | D32: ='Semana 4'!D32 | F32: ='Semana 4'!F32 | G32: ='Semana 4'!G32 | H32: ='Semana 4'!H32 | I32: ='Semana 4'!I32 | J32: ='Semana 4'!J32 | K32: ='Semana 4'!K32 | L32: ='Semana 4'!L32 | M32: ='Semana 4'!M32 | ... R32: ='Semana 4'!R32 | S32: =I32*J32+K32*L32+M32*N32+O32*P32+Q32*R32 -> 0
C33: ='Semana 4'!C33 | D33: ='Semana 4'!D33 | F33: ='Semana 4'!F33 | G33: ='Semana 4'!G33 | H33: ='Semana 4'!H33 | I33: ='Semana 4'!I33 | J33: ='Semana 4'!J33 | K33: ='Semana 4'!K33 | L33: ='Semana 4'!L33 | M33: ='Semana 4'!M33 | ... R33: ='Semana 4'!R33 | S33: =I33*J33+K33*L33+M33*N33+O33*P33+Q33*R33 -> 0
C34: ='Semana 4'!C34 | D34: ='Semana 4'!D34 | F34: ='Semana 4'!F34 | G34: ='Semana 4'!G34 | H34: ='Semana 4'!H34 | I34: ='Semana 4'!I34 | J34: ='Semana 4'!J34 | K34: ='Semana 4'!K34 | L34: ='Semana 4'!L34 | M34: ='Semana 4'!M34 | ... R34: ='Semana 4'!R34 | S34: =I34*J34+K34*L34+M34*N34+O34*P34+Q34*R34 -> 0
C35: ='Semana 4'!C35 | D35: ='Semana 4'!D35 | F35: ='Semana 4'!F35 | G35: ='Semana 4'!G35 | H35: ='Semana 4'!H35 | I35: ='Semana 4'!I35 | J35: ='Semana 4'!J35 | K35: ='Semana 4'!K35 | L35: ='Semana 4'!L35 | M35: ='Semana 4'!M35 | ... R35: ='Semana 4'!R35 | S35: =I35*J35+K35*L35+M35*N35+O35*P35+Q35*R35 -> 0
C36: ='Semana 4'!C36 | D36: ='Semana 4'!D36 | F36: ='Semana 4'!F36 | G36: ='Semana 4'!G36 | H36: ='Semana 4'!H36 | I36: ='Semana 4'!I36 | J36: ='Semana 4'!J36 | K36: ='Semana 4'!K36 | L36: ='Semana 4'!L36 | M36: ='Semana 4'!M36 | ... R36: ='Semana 4'!R36 | S36: =I36*J36+K36*L36+M36*N36+O36*P36+Q36*R36 -> 0
C37: ='Semana 4'!C37 | D37: ='Semana 4'!D37 | F37: ='Semana 4'!F37 | G37: ='Semana 4'!G37 | H37: ='Semana 4'!H37 | I37: ='Semana 4'!I37 | J37: ='Semana 4'!J37 | K37: ='Semana 4'!K37 | L37: ='Semana 4'!L37 | M37: ='Semana 4'!M37 | ... R37: ='Semana 4'!R37 | S37: =I37*J37+K37*L37+M37*N37+O37*P37+Q37*R37 -> 0
C38: ='Semana 4'!C38 | D38: ='Semana 4'!D38 | F38: ='Semana 4'!F38 | G38: ='Semana 4'!G38 | H38: ='Semana 4'!H38 | I38: ='Semana 4'!I38 | J38: ='Semana 4'!J38 | K38: ='Semana 4'!K38 | L38: ='Semana 4'!L38 | M38: ='Semana 4'!M38 | ... R38: ='Semana 4'!R38 | S38: =I38*J38+K38*L38+M38*N38+O38*P38+Q38*R38 -> 0
B39: Duración de la sesión | D39: DOMS | F39: GRUPO MUSCULAR | M39: PESAJE DEL DÍA | Q39: ESFUERZO GRAL.
B41: ='Semana 4'!B41 -> DÍA 4: ESTRUCTURA | F41: Series | G41: RIR/RPE | H41: Descanso | I41: Serie 1 | K41: Serie 2 | M41: Serie 3 | O41: Serie 4 | Q41: Serie 5 | S41: Tonelaje
B42: Notas del alumno | C42: Categoría de ejercicio | D42: Ejercicios | E42: Feedback Técnico | I42: Reps | J42: Kg | K42: Reps | L42: Kg | M42: Reps | N42: Kg | O42: Reps | P42: Kg | Q42: Reps | R42: Kg
C43: ='Semana 4'!C43 | D43: ='Semana 4'!D43 | F43: ='Semana 4'!F43 | G43: ='Semana 4'!G43 | H43: ='Semana 4'!H43 | I43: ='Semana 4'!I43 | J43: ='Semana 4'!J43 | K43: ='Semana 4'!K43 | L43: ='Semana 4'!L43 | M43: ='Semana 4'!M43 | ... R43: ='Semana 4'!R43 | S43: =I43*J43+K43*L43+M43*N43+O43*P43+Q43*R43 -> 0
C44: ='Semana 4'!C44 | D44: ='Semana 4'!D44 | F44: ='Semana 4'!F44 | G44: ='Semana 4'!G44 | H44: ='Semana 4'!H44 | I44: ='Semana 4'!I44 | J44: ='Semana 4'!J44 | K44: ='Semana 4'!K44 | L44: ='Semana 4'!L44 | M44: ='Semana 4'!M44 | ... R44: ='Semana 4'!R44 | S44: =I44*J44+K44*L44+M44*N44+O44*P44+Q44*R44 -> 0
C45: ='Semana 4'!C45 | D45: ='Semana 4'!D45 | F45: ='Semana 4'!F45 | G45: ='Semana 4'!G45 | H45: ='Semana 4'!H45 | I45: ='Semana 4'!I45 | J45: ='Semana 4'!J45 | K45: ='Semana 4'!K45 | L45: ='Semana 4'!L45 | M45: ='Semana 4'!M45 | ... R45: ='Semana 4'!R45 | S45: =I45*J45+K45*L45+M45*N45+O45*P45+Q45*R45 -> 0
...

Sheet Semana 6
C2: Entrenador/a | D2: ='Semana 1'!D2 -> Tu nombre y apellido | F2: Fecha de hoy | I2: =TODAY() -> 46305 | P2: Semanas trascurridas
C3: Nombre del alumno | D3: ='Semana 1'!D3 -> El nombre y apellido del alumno | F3: Fecha de inicio | I3: ='Semana 1'!I3 -> 45901 | P3: ='Semana 1'!P3 -> 57
B5: ='Semana 5'!B5 -> DÍA 1: ESTRUCTURA | F5: Series | G5: RIR/RPE | H5: Descanso | I5: Serie 1 | K5: Serie 2 | M5: Serie 3 | O5: Serie 4 | Q5: Serie 5 | S5: Tonelaje
B6: Notas del alumno | C6: Categoría de ejercicio | D6: Ejercicios | E6: Feedback Técnico | I6: Reps | J6: Kg | K6: Reps | L6: Kg | M6: Reps | N6: Kg | O6: Reps | P6: Kg | Q6: Reps | R6: Kg
C7: ='Semana 5'!C7 | D7: ='Semana 5'!D7 | F7: ='Semana 5'!F7 | G7: ='Semana 5'!G7 | H7: ='Semana 5'!H7 | I7: ='Semana 5'!I7 | J7: ='Semana 5'!J7 | K7: ='Semana 5'!K7 | L7: ='Semana 5'!L7 | M7: ='Semana 5'!M7 | ... R7: ='Semana 5'!R7 | S7: =I7*J7+K7*L7+M7*N7+O7*P7+Q7*R7 -> 0
C8: ='Semana 5'!C8 | D8: ='Semana 5'!D8 | F8: ='Semana 5'!F8 | G8: ='Semana 5'!G8 | H8: ='Semana 5'!H8 | I8: ='Semana 5'!I8 | J8: ='Semana 5'!J8 | K8: ='Semana 5'!K8 | L8: ='Semana 5'!L8 | M8: ='Semana 5'!M8 | ... R8: ='Semana 5'!R8 | S8: =I8*J8+K8*L8+M8*N8+O8*P8+Q8*R8 -> 0
C9: ='Semana 5'!C9 | D9: ='Semana 5'!D9 | F9: ='Semana 5'!F9 | G9: ='Semana 5'!G9 | H9: ='Semana 5'!H9 | I9: ='Semana 5'!I9 | J9: ='Semana 5'!J9 | K9: ='Semana 5'!K9 | L9: ='Semana 5'!L9 | M9: ='Semana 5'!M9 | ... R9: ='Semana 5'!R9 | S9: =I9*J9+K9*L9+M9*N9+O9*P9+Q9*R9 -> 0
C10: ='Semana 5'!C10 | D10: ='Semana 5'!D10 | F10: ='Semana 5'!F10 | G10: ='Semana 5'!G10 | H10: ='Semana 5'!H10 | I10: ='Semana 5'!I10 | J10: ='Semana 5'!J10 | K10: ='Semana 5'!K10 | L10: ='Semana 5'!L10 | M10: ='Semana 5'!M10 | ... R10: ='Semana 5'!R10 | S10: =I10*J10+K10*L10+M10*N10+O10*P10+Q10*R10 -> 0
C11: ='Semana 5'!C11 | D11: ='Semana 5'!D11 | F11: ='Semana 5'!F11 | G11: ='Semana 5'!G11 | H11: ='Semana 5'!H11 | I11: ='Semana 5'!I11 | J11: ='Semana 5'!J11 | K11: ='Semana 5'!K11 | L11: ='Semana 5'!L11 | M11: ='Semana 5'!M11 | ... R11: ='Semana 5'!R11 | S11: =I11*J11+K11*L11+M11*N11+O11*P11+Q11*R11 -> 0
C12: ='Semana 5'!C12 | D12: ='Semana 5'!D12 | F12: ='Semana 5'!F12 | G12: ='Semana 5'!G12 | H12: ='Semana 5'!H12 | I12: ='Semana 5'!I12 | J12: ='Semana 5'!J12 | K12: ='Semana 5'!K12 | L12: ='Semana 5'!L12 | M12: ='Semana 5'!M12 | ... R12: ='Semana 5'!R12 | S12: =I12*J12+K12*L12+M12*N12+O12*P12+Q12*R12 -> 0
C13: ='Semana 5'!C13 | D13: ='Semana 5'!D13 | F13: ='Semana 5'!F13 | G13: ='Semana 5'!G13 | H13: ='Semana 5'!H13 | I13: ='Semana 5'!I13 | J13: ='Semana 5'!J13 | K13: ='Semana 5'!K13 | L13: ='Semana 5'!L13 | M13: ='Semana 5'!M13 | ... R13: ='Semana 5'!R13 | S13: =I13*J13+K13*L13+M13*N13+O13*P13+Q13*R13 -> 0
C14: ='Semana 5'!C14 | D14: ='Semana 5'!D14 | F14: ='Semana 5'!F14 | G14: ='Semana 5'!G14 | H14: ='Semana 5'!H14 | I14: ='Semana 5'!I14 | J14: ='Semana 5'!J14 | K14: ='Semana 5'!K14 | L14: ='Semana 5'!L14 | M14: ='Semana 5'!M14 | ... R14: ='Semana 5'!R14 | S14: =I14*J14+K14*L14+M14*N14+O14*P14+Q14*R14 -> 0
B15: Duración de la sesión | D15: DOMS | F15: GRUPO MUSCULAR | M15: PESAJE DEL DÍA | Q15: ESFUERZO GRAL.
B17: ='Semana 5'!B17 -> DÍA 2: ESTRUCTURA | F17: Series | G17: RIR/RPE | H17: Descanso | I17: Serie 1 | K17: Serie 2 | M17: Serie 3 | O17: Serie 4 | Q17: Serie 5 | S17: Tonelaje
B18: Notas del alumno | C18: Categoría de ejercicio | D18: Ejercicios | E18: Feedback Técnico | I18: Reps | J18: Kg | K18: Reps | L18: Kg | M18: Reps | N18: Kg | O18: Reps | P18: Kg | Q18: Reps | R18: Kg
C19: ='Semana 5'!C19 | D19: ='Semana 5'!D19 | F19: ='Semana 5'!F19 | G19: ='Semana 5'!G19 | H19: ='Semana 5'!H19 | I19: ='Semana 5'!I19 | J19: ='Semana 5'!J19 | K19: ='Semana 5'!K19 | L19: ='Semana 5'!L19 | M19: ='Semana 5'!M19 | ... R19: ='Semana 5'!R19 | S19: =I19*J19+K19*L19+M19*N19+O19*P19+Q19*R19 -> 0
C20: ='Semana 5'!C20 | D20: ='Semana 5'!D20 | F20: ='Semana 5'!F20 | G20: ='Semana 5'!G20 | H20: ='Semana 5'!H20 | I20: ='Semana 5'!I20 | J20: ='Semana 5'!J20 | K20: ='Semana 5'!K20 | L20: ='Semana 5'!L20 | M20: ='Semana 5'!M20 | ... R20: ='Semana 5'!R20 | S20: =I20*J20+K20*L20+M20*N20+O20*P20+Q20*R20 -> 0
C21: ='Semana 5'!C21 | D21: ='Semana 5'!D21 | F21: ='Semana 5'!F21 | G21: ='Semana 5'!G21 | H21: ='Semana 5'!H21 | I21: ='Semana 5'!I21 | J21: ='Semana 5'!J21 | K21: ='Semana 5'!K21 | L21: ='Semana 5'!L21 | M21: ='Semana 5'!M21 | ... R21: ='Semana 5'!R21 | S21: =I21*J21+K21*L21+M21*N21+O21*P21+Q21*R21 -> 0
C22: ='Semana 5'!C22 | D22: ='Semana 5'!D22 | F22: ='Semana 5'!F22 | G22: ='Semana 5'!G22 | H22: ='Semana 5'!H22 | I22: ='Semana 5'!I22 | J22: ='Semana 5'!J22 | K22: ='Semana 5'!K22 | L22: ='Semana 5'!L22 | M22: ='Semana 5'!M22 | ... R22: ='Semana 5'!R22 | S22: =I22*J22+K22*L22+M22*N22+O22*P22+Q22*R22 -> 0
C23: ='Semana 5'!C23 | D23: ='Semana 5'!D23 | F23: ='Semana 5'!F23 | G23: ='Semana 5'!G23 | H23: ='Semana 5'!H23 | I23: ='Semana 5'!I23 | J23: ='Semana 5'!J23 | K23: ='Semana 5'!K23 | L23: ='Semana 5'!L23 | M23: ='Semana 5'!M23 | ... R23: ='Semana 5'!R23 | S23: =I23*J23+K23*L23+M23*N23+O23*P23+Q23*R23 -> 0
C24: ='Semana 5'!C24 | D24: ='Semana 5'!D24 | F24: ='Semana 5'!F24 | G24: ='Semana 5'!G24 | H24: ='Semana 5'!H24 | I24: ='Semana 5'!I24 | J24: ='Semana 5'!J24 | K24: ='Semana 5'!K24 | L24: ='Semana 5'!L24 | M24: ='Semana 5'!M24 | ... R24: ='Semana 5'!R24 | S24: =I24*J24+K24*L24+M24*N24+O24*P24+Q24*R24 -> 0
C25: ='Semana 5'!C25 | D25: ='Semana 5'!D25 | F25: ='Semana 5'!F25 | G25: ='Semana 5'!G25 | H25: ='Semana 5'!H25 | I25: ='Semana 5'!I25 | J25: ='Semana 5'!J25 | K25: ='Semana 5'!K25 | L25: ='Semana 5'!L25 | M25: ='Semana 5'!M25 | ... R25: ='Semana 5'!R25 | S25: =I25*J25+K25*L25+M25*N25+O25*P25+Q25*R25 -> 0
C26: ='Semana 5'!C26 | D26: ='Semana 5'!D26 | F26: ='Semana 5'!F26 | G26: ='Semana 5'!G26 | H26: ='Semana 5'!H26 | I26: ='Semana 5'!I26 | J26: ='Semana 5'!J26 | K26: ='Semana 5'!K26 | L26: ='Semana 5'!L26 | M26: ='Semana 5'!M26 | ... R26: ='Semana 5'!R26 | S26: =I26*J26+K26*L26+M26*N26+O26*P26+Q26*R26 -> 0
B27: Duración de la sesión | D27: DOMS | F27: GRUPO MUSCULAR | M27: PESAJE DEL DÍA | Q27: ESFUERZO GRAL.
B29: ='Semana 5'!B29 -> DÍA 3: ESTRUCTURA | F29: Series | G29: RIR/RPE | H29: Descanso | I29: Serie 1 | K29: Serie 2 | M29: Serie 3 | O29: Serie 4 | Q29: Serie 5 | S29: Tonelaje
B30: Notas del alumno | C30: Categoría de ejercicio | D30: Ejercicios | E30: Feedback Técnico | I30: Reps | J30: Kg | K30: Reps | L30: Kg | M30: Reps | N30: Kg | O30: Reps | P30: Kg | Q30: Reps | R30: Kg
C31: ='Semana 5'!C31 | D31: ='Semana 5'!D31 | F31: ='Semana 5'!F31 | G31: ='Semana 5'!G31 | H31: ='Semana 5'!H31 | I31: ='Semana 5'!I31 | J31: ='Semana 5'!J31 | K31: ='Semana 5'!K31 | L31: ='Semana 5'!L31 | M31: ='Semana 5'!M31 | ... R31: ='Semana 5'!R31 | S31: =I31*J31+K31*L31+M31*N31+O31*P31+Q31*R31 -> 0
C32: ='Semana 5'!C32 | D32: ='Semana 5'!D32 | F32: ='Semana 5'!F32 | G32: ='Semana 5'!G32 | H32: ='Semana 5'!H32 | I32: ='Semana 5'!I32 | J32: ='Semana 5'!J32 | K32: ='Semana 5'!K32 | L32: ='Semana 5'!L32 | M32: ='Semana 5'!M32 | ... R32: ='Semana 5'!R32 | S32: =I32*J32+K32*L32+M32*N32+O32*P32+Q32*R32 -> 0
C33: ='Semana 5'!C33 | D33: ='Semana 5'!D33 | F33: ='Semana 5'!F33 | G33: ='Semana 5'!G33 | H33: ='Semana 5'!H33 | I33: ='Semana 5'!I33 | J33: ='Semana 5'!J33 | K33: ='Semana 5'!K33 | L33: ='Semana 5'!L33 | M33: ='Semana 5'!M33 | ... R33: ='Semana 5'!R33 | S33: =I33*J33+K33*L33+M33*N33+O33*P33+Q33*R33 -> 0
C34: ='Semana 5'!C34 | D34: ='Semana 5'!D34 | F34: ='Semana 5'!F34 | G34: ='Semana 5'!G34 | H34: ='Semana 5'!H34 | I34: ='Semana 5'!I34 | J34: ='Semana 5'!J34 | K34: ='Semana 5'!K34 | L34: ='Semana 5'!L34 | M34: ='Semana 5'!M34 | ... R34: ='Semana 5'!R34 | S34: =I34*J34+K34*L34+M34*N34+O34*P34+Q34*R34 -> 0
C35: ='Semana 5'!C35 | D35: ='Semana 5'!D35 | F35: ='Semana 5'!F35 | G35: ='Semana 5'!G35 | H35: ='Semana 5'!H35 | I35: ='Semana 5'!I35 | J35: ='Semana 5'!J35 | K35: ='Semana 5'!K35 | L35: ='Semana 5'!L35 | M35: ='Semana 5'!M35 | ... R35: ='Semana 5'!R35 | S35: =I35*J35+K35*L35+M35*N35+O35*P35+Q35*R35 -> 0
C36: ='Semana 5'!C36 | D36: ='Semana 5'!D36 | F36: ='Semana 5'!F36 | G36: ='Semana 5'!G36 | H36: ='Semana 5'!H36 | I36: ='Semana 5'!I36 | J36: ='Semana 5'!J36 | K36: ='Semana 5'!K36 | L36: ='Semana 5'!L36 | M36: ='Semana 5'!M36 | ... R36: ='Semana 5'!R36 | S36: =I36*J36+K36*L36+M36*N36+O36*P36+Q36*R36 -> 0
C37: ='Semana 5'!C37 | D37: ='Semana 5'!D37 | F37: ='Semana 5'!F37 | G37: ='Semana 5'!G37 | H37: ='Semana 5'!H37 | I37: ='Semana 5'!I37 | J37: ='Semana 5'!J37 | K37: ='Semana 5'!K37 | L37: ='Semana 5'!L37 | M37: ='Semana 5'!M37 | ... R37: ='Semana 5'!R37 | S37: =I37*J37+K37*L37+M37*N37+O37*P37+Q37*R37 -> 0
C38: ='Semana 5'!C38 | D38: ='Semana 5'!D38 | F38: ='Semana 5'!F38 | G38: ='Semana 5'!G38 | H38: ='Semana 5'!H38 | I38: ='Semana 5'!I38 | J38: ='Semana 5'!J38 | K38: ='Semana 5'!K38 | L38: ='Semana 5'!L38 | M38: ='Semana 5'!M38 | ... R38: ='Semana 5'!R38 | S38: =I38*J38+K38*L38+M38*N38+O38*P38+Q38*R38 -> 0
B39: Duración de la sesión | D39: DOMS | F39: GRUPO MUSCULAR | M39: PESAJE DEL DÍA | Q39: ESFUERZO GRAL.
B41: ='Semana 5'!B41 -> DÍA 4: ESTRUCTURA | F41: Series | G41: RIR/RPE | H41: Descanso | I41: Serie 1 | K41: Serie 2 | M41: Serie 3 | O41: Serie 4 | Q41: Serie 5 | S41: Tonelaje
B42: Notas del alumno | C42: Categoría de ejercicio | D42: Ejercicios | E42: Feedback Técnico | I42: Reps | J42: Kg | K42: Reps | L42: Kg | M42: Reps | N42: Kg | O42: Reps | P42: Kg | Q42: Reps | R42: Kg
C43: ='Semana 5'!C43 | D43: ='Semana 5'!D43 | F43: ='Semana 5'!F43 | G43: ='Semana 5'!G43 | H43: ='Semana 5'!H43 | I43: ='Semana 5'!I43 | J43: ='Semana 5'!J43 | K43: ='Semana 5'!K43 | L43: ='Semana 5'!L43 | M43: ='Semana 5'!M43 | ... R43: ='Semana 5'!R43 | S43: =I43*J43+K43*L43+M43*N43+O43*P43+Q43*R43 -> 0
C44: ='Semana 5'!C44 | D44: ='Semana 5'!D44 | F44: ='Semana 5'!F44 | G44: ='Semana 5'!G44 | H44: ='Semana 5'!H44 | I44: ='Semana 5'!I44 | J44: ='Semana 5'!J44 | K44: ='Semana 5'!K44 | L44: ='Semana 5'!L44 | M44: ='Semana 5'!M44 | ... R44: ='Semana 5'!R44 | S44: =I44*J44+K44*L44+M44*N44+O44*P44+Q44*R44 -> 0
C45: ='Semana 5'!C45 | D45: ='Semana 5'!D45 | F45: ='Semana 5'!F45 | G45: ='Semana 5'!G45 | H45: ='Semana 5'!H45 | I45: ='Semana 5'!I45 | J45: ='Semana 5'!J45 | K45: ='Semana 5'!K45 | L45: ='Semana 5'!L45 | M45: ='Semana 5'!M45 | ... R45: ='Semana 5'!R45 | S45: =I45*J45+K45*L45+M45*N45+O45*P45+Q45*R45 -> 0
...

Sheet Semana 7
C2: Entrenador/a | D2: ='Semana 1'!D2 -> Tu nombre y apellido | F2: Fecha de hoy | I2: =TODAY() -> 46305 | P2: Semanas trascurridas
C3: Nombre del alumno | D3: ='Semana 1'!D3 -> El nombre y apellido del alumno | F3: Fecha de inicio | I3: ='Semana 1'!I3 -> 45901 | P3: ='Semana 1'!P3 -> 57
B5: ='Semana 6'!B5 -> DÍA 1: ESTRUCTURA | F5: Series | G5: RIR/RPE | H5: Descanso | I5: Serie 1 | K5: Serie 2 | M5: Serie 3 | O5: Serie 4 | Q5: Serie 5 | S5: Tonelaje
B6: Notas del alumno | C6: Categoría de ejercicio | D6: Ejercicios | E6: Feedback Técnico | I6: Reps | J6: Kg | K6: Reps | L6: Kg | M6: Reps | N6: Kg | O6: Reps | P6: Kg | Q6: Reps | R6: Kg
C7: ='Semana 6'!C7 | D7: ='Semana 6'!D7 | F7: ='Semana 6'!F7 | G7: ='Semana 6'!G7 | H7: ='Semana 6'!H7 | I7: ='Semana 6'!I7 | J7: ='Semana 6'!J7 | K7: ='Semana 6'!K7 | L7: ='Semana 6'!L7 | M7: ='Semana 6'!M7 | ... R7: ='Semana 6'!R7 | S7: =I7*J7+K7*L7+M7*N7+O7*P7+Q7*R7 -> 0
C8: ='Semana 6'!C8 | D8: ='Semana 6'!D8 | F8: ='Semana 6'!F8 | G8: ='Semana 6'!G8 | H8: ='Semana 6'!H8 | I8: ='Semana 6'!I8 | J8: ='Semana 6'!J8 | K8: ='Semana 6'!K8 | L8: ='Semana 6'!L8 | M8: ='Semana 6'!M8 | ... R8: ='Semana 6'!R8 | S8: =I8*J8+K8*L8+M8*N8+O8*P8+Q8*R8 -> 0
C9: ='Semana 6'!C9 | D9: ='Semana 6'!D9 | F9: ='Semana 6'!F9 | G9: ='Semana 6'!G9 | H9: ='Semana 6'!H9 | I9: ='Semana 6'!I9 | J9: ='Semana 6'!J9 | K9: ='Semana 6'!K9 | L9: ='Semana 6'!L9 | M9: ='Semana 6'!M9 | ... R9: ='Semana 6'!R9 | S9: =I9*J9+K9*L9+M9*N9+O9*P9+Q9*R9 -> 0
C10: ='Semana 6'!C10 | D10: ='Semana 6'!D10 | F10: ='Semana 6'!F10 | G10: ='Semana 6'!G10 | H10: ='Semana 6'!H10 | I10: ='Semana 6'!I10 | J10: ='Semana 6'!J10 | K10: ='Semana 6'!K10 | L10: ='Semana 6'!L10 | M10: ='Semana 6'!M10 | ... R10: ='Semana 6'!R10 | S10: =I10*J10+K10*L10+M10*N10+O10*P10+Q10*R10 -> 0
C11: ='Semana 6'!C11 | D11: ='Semana 6'!D11 | F11: ='Semana 6'!F11 | G11: ='Semana 6'!G11 | H11: ='Semana 6'!H11 | I11: ='Semana 6'!I11 | J11: ='Semana 6'!J11 | K11: ='Semana 6'!K11 | L11: ='Semana 6'!L11 | M11: ='Semana 6'!M11 | ... R11: ='Semana 6'!R11 | S11: =I11*J11+K11*L11+M11*N11+O11*P11+Q11*R11 -> 0
C12: ='Semana 6'!C12 | D12: ='Semana 6'!D12 | F12: ='Semana 6'!F12 | G12: ='Semana 6'!G12 | H12: ='Semana 6'!H12 | I12: ='Semana 6'!I12 | J12: ='Semana 6'!J12 | K12: ='Semana 6'!K12 | L12: ='Semana 6'!L12 | M12: ='Semana 6'!M12 | ... R12: ='Semana 6'!R12 | S12: =I12*J12+K12*L12+M12*N12+O12*P12+Q12*R12 -> 0
C13: ='Semana 6'!C13 | D13: ='Semana 6'!D13 | F13: ='Semana 6'!F13 | G13: ='Semana 6'!G13 | H13: ='Semana 6'!H13 | I13: ='Semana 6'!I13 | J13: ='Semana 6'!J13 | K13: ='Semana 6'!K13 | L13: ='Semana 6'!L13 | M13: ='Semana 6'!M13 | ... R13: ='Semana 6'!R13 | S13: =I13*J13+K13*L13+M13*N13+O13*P13+Q13*R13 -> 0
C14: ='Semana 6'!C14 | D14: ='Semana 6'!D14 | F14: ='Semana 6'!F14 | G14: ='Semana 6'!G14 | H14: ='Semana 6'!H14 | I14: ='Semana 6'!I14 | J14: ='Semana 6'!J14 | K14: ='Semana 6'!K14 | L14: ='Semana 6'!L14 | M14: ='Semana 6'!M14 | ... R14: ='Semana 6'!R14 | S14: =I14*J14+K14*L14+M14*N14+O14*P14+Q14*R14 -> 0
B15: Duración de la sesión | D15: DOMS | F15: GRUPO MUSCULAR | M15: PESAJE DEL DÍA | Q15: ESFUERZO GRAL.
B17: ='Semana 6'!B17 -> DÍA 2: ESTRUCTURA | F17: Series | G17: RIR/RPE | H17: Descanso | I17: Serie 1 | K17: Serie 2 | M17: Serie 3 | O17: Serie 4 | Q17: Serie 5 | S17: Tonelaje
B18: Notas del alumno | C18: Categoría de ejercicio | D18: Ejercicios | E18: Feedback Técnico | I18: Reps | J18: Kg | K18: Reps | L18: Kg | M18: Reps | N18: Kg | O18: Reps | P18: Kg | Q18: Reps | R18: Kg
C19: ='Semana 6'!C19 | D19: ='Semana 6'!D19 | F19: ='Semana 6'!F19 | G19: ='Semana 6'!G19 | H19: ='Semana 6'!H19 | I19: ='Semana 6'!I19 | J19: ='Semana 6'!J19 | K19: ='Semana 6'!K19 | L19: ='Semana 6'!L19 | M19: ='Semana 6'!M19 | ... R19: ='Semana 6'!R19 | S19: =I19*J19+K19*L19+M19*N19+O19*P19+Q19*R19 -> 0
C20: ='Semana 6'!C20 | D20: ='Semana 6'!D20 | F20: ='Semana 6'!F20 | G20: ='Semana 6'!G20 | H20: ='Semana 6'!H20 | I20: ='Semana 6'!I20 | J20: ='Semana 6'!J20 | K20: ='Semana 6'!K20 | L20: ='Semana 6'!L20 | M20: ='Semana 6'!M20 | ... R20: ='Semana 6'!R20 | S20: =I20*J20+K20*L20+M20*N20+O20*P20+Q20*R20 -> 0
C21: ='Semana 6'!C21 | D21: ='Semana 6'!D21 | F21: ='Semana 6'!F21 | G21: ='Semana 6'!G21 | H21: ='Semana 6'!H21 | I21: ='Semana 6'!I21 | J21: ='Semana 6'!J21 | K21: ='Semana 6'!K21 | L21: ='Semana 6'!L21 | M21: ='Semana 6'!M21 | ... R21: ='Semana 6'!R21 | S21: =I21*J21+K21*L21+M21*N21+O21*P21+Q21*R21 -> 0
C22: ='Semana 6'!C22 | D22: ='Semana 6'!D22 | F22: ='Semana 6'!F22 | G22: ='Semana 6'!G22 | H22: ='Semana 6'!H22 | I22: ='Semana 6'!I22 | J22: ='Semana 6'!J22 | K22: ='Semana 6'!K22 | L22: ='Semana 6'!L22 | M22: ='Semana 6'!M22 | ... R22: ='Semana 6'!R22 | S22: =I22*J22+K22*L22+M22*N22+O22*P22+Q22*R22 -> 0
